Workbook

Sheet Rack Master
A1: Rack ID | B1: Rack Type | C1: Source Description | D1: Bay Count (VERIFY) | E1: Levels | F1: Side Requirement (VERIFY) | G1: Status | H1: Source Note
A2: R01 | B2: Pallet Rack | C2: Rack 1 (4 Bays, 6 Levels) | D2: 4 | E2: GL1, GL2, GL3, SL4, SL5, SL6 | F2: Double-sided | G2: Verified / Active | H2: Verified from actual rack layout sheet
A3: R02 | B3: Pallet Rack | C3: Rack 2 (4 Bays, 6 Levels) | D3: 4 | E3: GL1, GL2, GL3, SL4, SL5, SL6 | F3: Double-sided | G3: Verified / Active | H3: Verified from actual rack layout sheet
A4: R03 | B4: Pallet Rack | C4: Rack 3 (4 Bays, 6 Levels) | D4: 4 | E4: GL1, GL2, GL3, SL4, SL5, SL6 | F4: Double-sided | G4: Verified / Active | H4: Verified from actual rack layout sheet
A5: R04 | B5: Pallet Rack | C5: Rack 4 (4 Bays, 6 Levels) | D5: 4 | E5: GL1, GL2, GL3, SL4, SL5, SL6 | F5: Double-sided | G5: Verified / Active | H5: Verified from actual rack layout sheet
A6: R05 | B6: Pallet Rack | C6: Rack 5 (4 Bays, 6 Levels) | D6: 4 | E6: GL1, GL2, GL3, SL4, SL5, SL6 | F6: Double-sided | G6: Verified / Active | H6: Verified from actual rack layout sheet
A7: R06 | B7: Pallet Rack | C7: Rack 6 (4 Bays, 6 Levels) | D7: 4 | E7: GL1, GL2, GL3, SL4, SL5, SL6 | F7: Double-sided | G7: Verified / Active | H7: Verified from actual rack layout sheet
A8: R07 | B8: Pallet Rack | C8: Rack 7 (4 Bays, 6 Levels) | D8: 4 | E8: GL1, GL2, GL3, SL4, SL5, SL6 | F8: Double-sided | G8: Verified / Active | H8: Verified from actual rack layout sheet
A9: R08 | B9: Pallet Rack | C9: Rack 8 (4 Bays, 6 Levels) | D9: 4 | E9: GL1, GL2, GL3, SL4, SL5, SL6 | F9: Double-sided | G9: Verified / Active | H9: Verified from actual rack layout sheet
A10: R09 | B10: Pallet Rack | C10: Rack 9 (4 Bays, 6 Levels) | D10: 4 | E10: GL1, GL2, GL3, SL4, SL5, SL6 | F10: Double-sided | G10: Verified / Active | H10: Verified from actual rack layout sheet
A11: R10 | B11: Pallet Rack | C11: Rack 10 (4 Bays, 6 Levels) | D11: 4 | E11: GL1, GL2, GL3, SL4, SL5, SL6 | F11: Double-sided | G11: Verified / Active | H11: Verified from actual rack layout sheet
A12: R11 | B12: Pallet Rack | C12: Rack 11 (4 Bays, 6 Levels) | D12: 4 | E12: GL1, GL2, GL3, SL4, SL5, SL6 | F12: Double-sided | G12: Verified / Active | H12: Verified from actual rack layout sheet
A15: Level Code | B15: Level Category | C15: Standard / Description | D15: Sub-Level / Sub-Option Guidance
A16: GL1 | B16: Ground Level | C16: GL1 = Ground Level 1 | D16: Sub-options: GL1-A, GL1-B (Subdivided shelving)
A17: GL2 | B17: Ground Level | C17: GL2 = Ground Level 2 | D17: Sub-options: GL2-A, GL2-B (Subdivided shelving)
A18: GL3 | B18: Ground Level | C18: GL3 = Ground Level 3 | D18: Sub-options: GL3-A, GL3-B (Subdivided shelving)
A19: SL1 | B19: Stilt Level | C19: SL1 = Stilt Level 1 (Optional/Sub) | D19: Sub-options: SL1-A, SL1-B (Optional stilt tier)
A20: SL2 | B20: Stilt Level | C20: SL2 = Ground/Stilt Option 2 | D20: Sub-options: SL2-A, SL2-B (Optional stilt tier)
A21: SL3 | B21: Stilt Level | C21: SL3 = Ground/Stilt Option 3 | D21: Sub-options: SL3-A, SL3-B (Optional stilt tier)
A22: SL4 | B22: Stilt Level | C22: SL4 = Stilt Level 4 | D22: Sub-options: SL4-A, SL4-B (Upper tier staging)
A23: SL5 | B23: Stilt Level | C23: SL5 = Stilt Level 5 | D23: Sub-options: SL5-A, SL5-B (Upper tier staging)
A24: SL6 | B24: Stilt Level | C24: SL6 = Stilt Level 6 | D24: Sub-options: SL6-A, SL6-B (Top tier storage)

Sheet Material Master
A1: Material ID | B1: Material Description | C1: Category | D1: Unit | E1: Reorder Level | F1: Material ID (Name)
A2: MAT001 | B2: BUBBLE WRAP | C2: PLUMBER | D2: PCS | E2: 10 | F2: =IF(A2="","",A2 & " (" & B2 & ")") -> MAT001 (BUBBLE WRAP)
A3: MAT002 | B3: CANDLE_LUGNARE_SCNTD | C3: DECOR | D3: PCS | E3: 25 | F3: =IF(A3="","",A3 & " (" & B3 & ")") -> MAT002 (CANDLE_LUGNARE_SCNTD)
A4: MAT003 | B4: EXTRA MCB | C4: ELECTRIC | D4: PCS | E4: 5 | F4: =IF(A4="","",A4 & " (" & B4 & ")") -> MAT003 (EXTRA MCB)
A5: MAT004 | B5: FOSSIAL | C5: CIVIL | D5: BAG | E5: 5 | F5: =IF(A5="","",A5 & " (" & B5 & ")") -> MAT004 (FOSSIAL)
A6: MAT005 | B6: GRANITE_ AVALANCHE | C6: CIVIL | D6: SQF | E6: 20 | F6: =IF(A6="","",A6 & " (" & B6 & ")") -> MAT005 (GRANITE_ AVALANCHE)
A7: MAT006 | B7: PLATE BLACK_12MODULE_ VIHAAN | C7: CARPENTER | D7: PCS | E7: 10 | F7: =IF(A7="","",A7 & " (" & B7 & ")") -> MAT006 (PLATE BLACK_12MODULE_ VIHAAN)
A8: MAT007 | B8: POLYCAB_1.5SQ MM 90_METER | C8: CARPENTER | D8: PCS | E8: 10 | F8: =IF(A8="","",A8 & " (" & B8 & ")") -> MAT007 (POLYCAB_1.5SQ MM 90_METER)
A9: MAT008 | B9: SCREW_DRYWALL-BLACK 19X6 | C9: ELECTRIC | D9: PCS | E9: 50 | F9: =IF(A9="","",A9 & " (" & B9 & ")") -> MAT008 (SCREW_DRYWALL-BLACK 19X6)
A10: MAT009 | B10: SCREW_DRYWALL-BLACK-75X6 | C10: ELECTRIC | D10: PCS | E10: 50 | F10: =IF(A10="","",A10 & " (" & B10 & ")") -> MAT009 (SCREW_DRYWALL-BLACK-75X6)
A11: MAT010 | B11: SCREW_SELF THREAD_25X6 | C11: ELECTRIC | D11: PCS | E11: 10 | F11: =IF(A11="","",A11 & " (" & B11 & ")") -> MAT010 (SCREW_SELF THREAD_25X6)
A12: MAT011 | B12: Silicon_BOND | C12: ELECTRIC | D12: PCS | E12: 10 | F12: =IF(A12="","",A12 & " (" & B12 & ")") -> MAT011 (Silicon_BOND)
A13: MAT012 | B13: SLUE PIPE_20MM | C13: AC | D13: PCS | E13: 5 | F13: =IF(A13="","",A13 & " (" & B13 & ")") -> MAT012 (SLUE PIPE_20MM)
... A50: MAT049 | B50: ALL MOTTLED | C50: ELECTRIC | D50: PCS | E50: 10 | F50: =IF(A50="","",A50 & " (" & B50 & ")") -> MAT049 (ALL MOTTLED)
F51: =IF(A51="","",A51 & " (" & B51 & ")")
F52: =IF(A52="","",A52 & " (" & B52 & ")")
F53: =IF(A53="","",A53 & " (" & B53 & ")")
F54: =IF(A54="","",A54 & " (" & B54 & ")")
F55: =IF(A55="","",A55 & " (" & B55 & ")")
F56: =IF(A56="","",A56 & " (" & B56 & ")")
F57: =IF(A57="","",A57 & " (" & B57 & ")")
F58: =IF(A58="","",A58 & " (" & B58 & ")")
F59: =IF(A59="","",A59 & " (" & B59 & ")")
F60: =IF(A60="","",A60 & " (" & B60 & ")")
F61: =IF(A61="","",A61 & " (" & B61 & ")")
F62: =IF(A62="","",A62 & " (" & B62 & ")")
... F201: =IF(A201="","",A201 & " (" & B201 & ")")

Sheet Location Master
A1: Rack | B1: Bay | C1: Level | D1: Slot | E1: Location ID | F1: Status | G1: Material ID | H1: Material Description | I1: Category | J1: Quantity | K1: Unit | L1: Batch/Lot | M1: Notes
A2: R01 | B2: 1 | C2: GL1 | D2: A1 | E2: =IF(COUNTA(A2:D2)=0,"",A2&"-"&"B"&TEXT(B2,"00")&"-"&C2&"-"&D2) -> R01-B01-GL1-A1 | F2: =IF(E2="","",IF(J2>0,"Occupied","Available")) -> Occupied | G2: MAT001 (BUBBLE WRAP) | H2: {=IF(G2="","",IFERROR(INDEX('Material Master'!$B$2:$B$201,IFERROR(MATCH(G2,'Material Master'!$F$2:$F$201,0),MATCH(G2,'Material Master'!$A$2:$A$201,0))),""))} -> BUBBLE WRAP | I2: {=IF(G2="","",IFERROR(INDEX('Material Master'!$C$2:$C$201,IFERROR(MATCH(G2,'Material Master'!$F$2:$F$201,0),MATCH(G2,'Material Master'!$A$2:$A$201,0))),""))} -> PLUMBER | J2: =IF(E2="","",SUMIFS('Stock Movement'!$F$2:$F$501,'Stock Movement'!$D$2:$D$501,E2,'Stock Movement'!$E$2:$E$501,"IN")-SUMIFS('Stock Movement'!$F$2:$F$501,'Stock Movement'!$D$2:$D$501,E2,'Stock Movement'!$E$2:$E$501,"OUT")) -> 100 | K2: {=IF(G2="","",IFERROR(INDEX('Material Master'!$D$2:$D$201,IFERROR(MATCH(G2,'Material Master'!$F$2:$F$201,0),MATCH(G2,'Material Master'!$A$2:$A$201,0))),""))} -> PCS | L2: LOT-2026-BW01 | M2: Padded packaging roll; dry storage
A3: R01 | B3: 1 | C3: GL1 | D3: A2 | E3: =IF(COUNTA(A3:D3)=0,"",A3&"-"&"B"&TEXT(B3,"00")&"-"&C3&"-"&D3) -> R01-B01-GL1-A2 | F3: =IF(E3="","",IF(J3>0,"Occupied","Available")) -> Available | G3: MAT043 (ALL BERRY STEM BLUE GG10) | H3: {=IF(G3="","",IFERROR(INDEX('Material Master'!$B$2:$B$201,IFERROR(MATCH(G3,'Material Master'!$F$2:$F$201,0),MATCH(G3,'Material Master'!$A$2:$A$201,0))),""))} -> ALL BERRY STEM BLUE GG10 | I3: {=IF(G3="","",IFERROR(INDEX('Material Master'!$C$2:$C$201,IFERROR(MATCH(G3,'Material Master'!$F$2:$F$201,0),MATCH(G3,'Material Master'!$A$2:$A$201,0))),""))} -> ELECTRIC | J3: =IF(E3="","",SUMIFS('Stock Movement'!$F$2:$F$501,'Stock Movement'!$D$2:$D$501,E3,'Stock Movement'!$E$2:$E$501,"IN")-SUMIFS('Stock Movement'!$F$2:$F$501,'Stock Movement'!$D$2:$D$501,E3,'Stock Movement'!$E$2:$E$501,"OUT")) -> 0 | K3: {=IF(G3="","",IFERROR(INDEX('Material Master'!$D$2:$D$201,IFERROR(MATCH(G3,'Material Master'!$F$2:$F$201,0),MATCH(G3,'Material Master'!$A$2:$A$201,0))),""))} -> PCS | L3: LOT-2026-BW02 | M3: Padded packaging roll; dry storage
A4: R01 | B4: 1 | C4: GL1 | D4: B | E4: =IF(COUNTA(A4:D4)=0,"",A4&"-"&"B"&TEXT(B4,"00")&"-"&C4&"-"&D4) -> R01-B01-GL1-B | F4: =IF(E4="","",IF(J4>0,"Occupied","Available")) -> Occupied | G4: MAT002 (CANDLE_LUGNARE_SCNTD) | H4: {=IF(G4="","",IFERROR(INDEX('Material Master'!$B$2:$B$201,IFERROR(MATCH(G4,'Material Master'!$F$2:$F$201,0),MATCH(G4,'Material Master'!$A$2:$A$201,0))),""))} -> CANDLE_LUGNARE_SCNTD | I4: {=IF(G4="","",IFERROR(INDEX('Material Master'!$C$2:$C$201,IFERROR(MATCH(G4,'Material Master'!$F$2:$F$201,0),MATCH(G4,'Material Master'!$A$2:$A$201,0))),""))} -> DECOR | J4: =IF(E4="","",SUMIFS('Stock Movement'!$F$2:$F$501,'Stock Movement'!$D$2:$D$501,E4,'Stock Movement'!$E$2:$E$501,"IN")-SUMIFS('Stock Movement'!$F$2:$F$501,'Stock Movement'!$D$2:$D$501,E4,'Stock Movement'!$E$2:$E$501,"OUT")) -> 138 | K4: {=IF(G4="","",IFERROR(INDEX('Material Master'!$D$2:$D$201,IFERROR(MATCH(G4,'Material Master'!$F$2:$F$201,0),MATCH(G4,'Material Master'!$A$2:$A$201,0))),""))} -> PCS | L4: LOT-2026-CD02 | M4: Scented candle cartons; keep away from direct heat
A5: R01 | B5: 1 | C5: GL2 | D5: A | E5: =IF(COUNTA(A5:D5)=0,"",A5&"-"&"B"&TEXT(B5,"00")&"-"&C5&"-"&D5) -> R01-B01-GL2-A | F5: =IF(E5="","",IF(J5>0,"Occupied","Available")) -> Occupied | G5: MAT003 (EXTRA MCB) | H5: {=IF(G5="","",IFERROR(INDEX('Material Master'!$B$2:$B$201,IFERROR(MATCH(G5,'Material Master'!$F$2:$F$201,0),MATCH(G5,'Material Master'!$A$2:$A$201,0))),""))} -> EXTRA MCB | I5: {=IF(G5="","",IFERROR(INDEX('Material Master'!$C$2:$C$201,IFERROR(MATCH(G5,'Material Master'!$F$2:$F$201,0),MATCH(G5,'Material Master'!$A$2:$A$201,0))),""))} -> ELECTRIC | J5: =IF(E5="","",SUMIFS('Stock Movement'!$F$2:$F$501,'Stock Movement'!$D$2:$D$501,E5,'Stock Movement'!$E$2:$E$501,"IN")-SUMIFS('Stock Movement'!$F$2:$F$501,'Stock Movement'!$D$2:$D$501,E5,'Stock Movement'!$E$2:$E$501,"OUT")) -> 1 | K5: {=IF(G5="","",IFERROR(INDEX('Material Master'!$D$2:$D$201,IFERROR(MATCH(G5,'Material Master'!$F$2:$F$201,0),MATCH(G5,'Material Master'!$A$2:$A$201,0))),""))} -> PCS | L5: LOT-2026-MC03 | M5: Electrical circuit breaker; secure dry bin
A6: R01 | B6: 1 | C6: GL2 | D6: B | E6: =IF(COUNTA(A6:D6)=0,"",A6&"-"&"B"&TEXT(B6,"00")&"-"&C6&"-"&D6) -> R01-B01-GL2-B | F6: =IF(E6="","",IF(J6>0,"Occupied","Available")) -> Occupied | G6: MAT004 (FOSSIAL) | H6: {=IF(G6="","",IFERROR(INDEX('Material Master'!$B$2:$B$201,IFERROR(MATCH(G6,'Material Master'!$F$2:$F$201,0),MATCH(G6,'Material Master'!$A$2:$A$201,0))),""))} -> FOSSIAL | I6: {=IF(G6="","",IFERROR(INDEX('Material Master'!$C$2:$C$201,IFERROR(MATCH(G6,'Material Master'!$F$2:$F$201,0),MATCH(G6,'Material Master'!$A$2:$A$201,0))),""))} -> CIVIL | J6: =IF(E6="","",SUMIFS('Stock Movement'!$F$2:$F$501,'Stock Movement'!$D$2:$D$501,E6,'Stock Movement'!$E$2:$E$501,"IN")-SUMIFS('Stock Movement'!$F$2:$F$501,'Stock Movement'!$D$2:$D$501,E6,'Stock Movement'!$E$2:$E$501,"OUT")) -> 3 | K6: {=IF(G6="","",IFERROR(INDEX('Material Master'!$D$2:$D$201,IFERROR(MATCH(G6,'Material Master'!$F$2:$F$201,0),MATCH(G6,'Material Master'!$A$2:$A$201,0))),""))} -> BAG | L6: LOT-2026-FS04 | M6: Civil adhesive bag; palletized floor clearance
A7: R01 | B7: 2 | C7: GL1 | D7: A | E7: =IF(COUNTA(A7:D7)=0,"",A7&"-"&"B"&TEXT(B7,"00")&"-"&C7&"-"&D7) -> R01-B02-GL1-A | F7: =IF(E7="","",IF(J7>0,"Occupied","Available")) -> Occupied | G7: MAT005 (GRANITE_ AVALANCHE) | H7: {=IF(G7="","",IFERROR(INDEX('Material Master'!$B$2:$B$201,IFERROR(MATCH(G7,'Material Master'!$F$2:$F$201,0),MATCH(G7,'Material Master'!$A$2:$A$201,0))),""))} -> GRANITE_ AVALANCHE | I7: {=IF(G7="","",IFERROR(INDEX('Material Master'!$C$2:$C$201,IFERROR(MATCH(G7,'Material Master'!$F$2:$F$201,0),MATCH(G7,'Material Master'!$A$2:$A$201,0))),""))} -> CIVIL | J7: =IF(E7="","",SUMIFS('Stock Movement'!$F$2:$F$501,'Stock Movement'!$D$2:$D$501,E7,'Stock Movement'!$E$2:$E$501,"IN")-SUMIFS('Stock Movement'!$F$2:$F$501,'Stock Movement'!$D$2:$D$501,E7,'Stock Movement'!$E$2:$E$501,"OUT")) -> 39.13 | K7: {=IF(G7="","",IFERROR(INDEX('Material Master'!$D$2:$D$201,IFERROR(MATCH(G7,'Material Master'!$F$2:$F$201,0),MATCH(G7,'Material Master'!$A$2:$A$201,0))),""))} -> SQF | L7: LOT-2026-GA05 | M7: Heavy granite slabs; vertical rack storage
A8: R01 | B8: 2 | C8: GL2 | D8: A | E8: =IF(COUNTA(A8:D8)=0,"",A8&"-"&"B"&TEXT(B8,"00")&"-"&C8&"-"&D8) -> R01-B02-GL2-A | F8: =IF(E8="","",IF(J8>0,"Occupied","Available")) -> Occupied | G8: MAT010 (SCREW_SELF THREAD_25X6) | H8: {=IF(G8="","",IFERROR(INDEX('Material Master'!$B$2:$B$201,IFERROR(MATCH(G8,'Material Master'!$F$2:$F$201,0),MATCH(G8,'Material Master'!$A$2:$A$201,0))),""))} -> SCREW_SELF THREAD_25X6 | I8: {=IF(G8="","",IFERROR(INDEX('Material Master'!$C$2:$C$201,IFERROR(MATCH(G8,'Material Master'!$F$2:$F$201,0),MATCH(G8,'Material Master'!$A$2:$A$201,0))),""))} -> ELECTRIC | J8: =IF(E8="","",SUMIFS('Stock Movement'!$F$2:$F$501,'Stock Movement'!$D$2:$D$501,E8,'Stock Movement'!$E$2:$E$501,"IN")-SUMIFS('Stock Movement'!$F$2:$F$501,'Stock Movement'!$D$2:$D$501,E8,'Stock Movement'!$E$2:$E$501,"OUT")) -> 2 | K8: {=IF(G8="","",IFERROR(INDEX('Material Master'!$D$2:$D$201,IFERROR(MATCH(G8,'Material Master'!$F$2:$F$201,0),MATCH(G8,'Material Master'!$A$2:$A$201,0))),""))} -> PCS | L8: LOT-2026-SC10 | M8: High-grade self threading screws carton
A9: R01 | B9: 2 | C9: GL2 | D9: B | E9: =IF(COUNTA(A9:D9)=0,"",A9&"-"&"B"&TEXT(B9,"00")&"-"&C9&"-"&D9) -> R01-B02-GL2-B | F9: =IF(E9="","",IF(J9>0,"Occupied","Available")) -> Occupied | G9: MAT012 (SLUE PIPE_20MM) | H9: {=IF(G9="","",IFERROR(INDEX('Material Master'!$B$2:$B$201,IFERROR(MATCH(G9,'Material Master'!$F$2:$F$201,0),MATCH(G9,'Material Master'!$A$2:$A$201,0))),""))} -> SLUE PIPE_20MM | I9: {=IF(G9="","",IFERROR(INDEX('Material Master'!$C$2:$C$201,IFERROR(MATCH(G9,'Material Master'!$F$2:$F$201,0),MATCH(G9,'Material Master'!$A$2:$A$201,0))),""))} -> AC | J9: =IF(E9="","",SUMIFS('Stock Movement'!$F$2:$F$501,'Stock Movement'!$D$2:$D$501,E9,'Stock Movement'!$E$2:$E$501,"IN")-SUMIFS('Stock Movement'!$F$2:$F$501,'Stock Movement'!$D$2:$D$501,E9,'Stock Movement'!$E$2:$E$501,"OUT")) -> 1 | K9: {=IF(G9="","",IFERROR(INDEX('Material Master'!$D$2:$D$201,IFERROR(MATCH(G9,'Material Master'!$F$2:$F$201,0),MATCH(G9,'Material Master'!$A$2:$A$201,0))),""))} -> PCS | L9: LOT-2026-SP12 | M9: Pipe fittings; HVAC storage section
A10: R01 | B10: 1 | C10: GL3 | D10: A | E10: =IF(COUNTA(A10:D10)=0,"",A10&"-"&"B"&TEXT(B10,"00")&"-"&C10&"-"&D10) -> R01-B01-GL3-A | F10: =IF(E10="","",IF(J10>0,"Occupied","Available")) -> Occupied | G10: MAT016 (2*10 WIRE NAIL) | H10: {=IF(G10="","",IFERROR(INDEX('Material Master'!$B$2:$B$201,IFERROR(MATCH(G10,'Material Master'!$F$2:$F$201,0),MATCH(G10,'Material Master'!$A$2:$A$201,0))),""))} -> 2*10 WIRE NAIL | I10: {=IF(G10="","",IFERROR(INDEX('Material Master'!$C$2:$C$201,IFERROR(MATCH(G10,'Material Master'!$F$2:$F$201,0),MATCH(G10,'Material Master'!$A$2:$A$201,0))),""))} -> FURNISHING | J10: =IF(E10="","",SUMIFS('Stock Movement'!$F$2:$F$501,'Stock Movement'!$D$2:$D$501,E10,'Stock Movement'!$E$2:$E$501,"IN")-SUMIFS('Stock Movement'!$F$2:$F$501,'Stock Movement'!$D$2:$D$501,E10,'Stock Movement'!$E$2:$E$501,"OUT")) -> 4 | K10: {=IF(G10="","",IFERROR(INDEX('Material Master'!$D$2:$D$201,IFERROR(MATCH(G10,'Material Master'!$F$2:$F$201,0),MATCH(G10,'Material Master'!$A$2:$A$201,0))),""))} -> PCS | L10: LOT-2026-WN16 | M10: Wire nails box; hardware rack section
A11: R01 | B11: 1 | C11: GL3 | D11: B | E11: =IF(COUNTA(A11:D11)=0,"",A11&"-"&"B"&TEXT(B11,"00")&"-"&C11&"-"&D11) -> R01-B01-GL3-B | F11: =IF(E11="","",IF(J11>0,"Occupied","Available")) -> Occupied | G11: MAT033 (ACP_8X4) | H11: {=IF(G11="","",IFERROR(INDEX('Material Master'!$B$2:$B$201,IFERROR(MATCH(G11,'Material Master'!$F$2:$F$201,0),MATCH(G11,'Material Master'!$A$2:$A$201,0))),""))} -> ACP_8X4 | I11: {=IF(G11="","",IFERROR(INDEX('Material Master'!$C$2:$C$201,IFERROR(MATCH(G11,'Material Master'!$F$2:$F$201,0),MATCH(G11,'Material Master'!$A$2:$A$201,0))),""))} -> ELECTRIC | J11: =IF(E11="","",SUMIFS('Stock Movement'!$F$2:$F$501,'Stock Movement'!$D$2:$D$501,E11,'Stock Movement'!$E$2:$E$501,"IN")-SUMIFS('Stock Movement'!$F$2:$F$501,'Stock Movement'!$D$2:$D$501,E11,'Stock Movement'!$E$2:$E$501,"OUT")) -> 10 | K11: {=IF(G11="","",IFERROR(INDEX('Material Master'!$D$2:$D$201,IFERROR(MATCH(G11,'Material Master'!$F$2:$F$201,0),MATCH(G11,'Material Master'!$A$2:$A$201,0))),""))} -> PCS | L11: LOT-2026-WN17 | M11: Open pallet position
A12: R01 | B12: 2 | C12: GL1 | D12: B | E12: =IF(COUNTA(A12:D12)=0,"",A12&"-"&"B"&TEXT(B12,"00")&"-"&C12&"-"&D12) -> R01-B02-GL1-B | F12: =IF(E12="","",IF(J12>0,"Occupied","Available")) -> Occupied | G12: MAT049 (ALL MOTTLED) | H12: {=IF(G12="","",IFERROR(INDEX('Material Master'!$B$2:$B$201,IFERROR(MATCH(G12,'Material Master'!$F$2:$F$201,0),MATCH(G12,'Material Master'!$A$2:$A$201,0))),""))} -> ALL MOTTLED | I12: {=IF(G12="","",IFERROR(INDEX('Material Master'!$C$2:$C$201,IFERROR(MATCH(G12,'Material Master'!$F$2:$F$201,0),MATCH(G12,'Material Master'!$A$2:$A$201,0))),""))} -> ELECTRIC | J12: =IF(E12="","",SUMIFS('Stock Movement'!$F$2:$F$501,'Stock Movement'!$D$2:$D$501,E12,'Stock Movement'!$E$2:$E$501,"IN")-SUMIFS('Stock Movement'!$F$2:$F$501,'Stock Movement'!$D$2:$D$501,E12,'Stock Movement'!$E$2:$E$501,"OUT")) -> 10 | K12: {=IF(G12="","",IFERROR(INDEX('Material Master'!$D$2:$D$201,IFERROR(MATCH(G12,'Material Master'!$F$2:$F$201,0),MATCH(G12,'Material Master'!$A$2:$A$201,0))),""))} -> PCS | L12: LOT-2026-B01 | M12: Open pallet position
A13: R01 | B13: 2 | C13: GL3 | D13: A | E13: =IF(COUNTA(A13:D13)=0,"",A13&"-"&"B"&TEXT(B13,"00")&"-"&C13&"-"&D13) -> R01-B02-GL3-A | F13: =IF(E13="","",IF(J13>0,"Occupied","Available")) -> Available | H13: {=IF(G13="","",IFERROR(INDEX('Material Master'!$B$2:$B$201,IFERROR(MATCH(G13,'Material Master'!$F$2:$F$201,0),MATCH(G13,'Material Master'!$A$2:$A$201,0))),""))} | I13: {=IF(G13="","",IFERROR(INDEX('Material Master'!$C$2:$C$201,IFERROR(MATCH(G13,'Material Master'!$F$2:$F$201,0),MATCH(G13,'Material Master'!$A$2:$A$201,0))),""))} | J13: =IF(E13="","",SUMIFS('Stock Movement'!$F$2:$F$501,'Stock Movement'!$D$2:$D$501,E13,'Stock Movement'!$E$2:$E$501,"IN")-SUMIFS('Stock Movement'!$F$2:$F$501,'Stock Movement'!$D$2:$D$501,E13,'Stock Movement'!$E$2:$E$501,"OUT")) -> 0 | K13: {=IF(G13="","",IFERROR(INDEX('Material Master'!$D$2:$D$201,IFERROR(MATCH(G13,'Material Master'!$F$2:$F$201,0),MATCH(G13,'Material Master'!$A$2:$A$201,0))),""))} | L13: LOT-2026-WN19 | M13: Open pallet position
A14: R02 | B14: 2 | C14: GL1 | D14: A | E14: =IF(COUNTA(A14:D14)=0,"",A14&"-"&"B"&TEXT(B14,"00")&"-"&C14&"-"&D14) -> R02-B02-GL1-A | F14: =IF(E14="","",IF(J14>0,"Occupied","Available")) -> Available | H14: {=IF(G14="","",IFERROR(INDEX('Material Master'!$B$2:$B$201,IFERROR(MATCH(G14,'Material Master'!$F$2:$F$201,0),MATCH(G14,'Material Master'!$A$2:$A$201,0))),""))} | I14: {=IF(G14="","",IFERROR(INDEX('Material Master'!$C$2:$C$201,IFERROR(MATCH(G14,'Material Master'!$F$2:$F$201,0),MATCH(G14,'Material Master'!$A$2:$A$201,0))),""))} | J14: =IF(E14="","",SUMIFS('Stock Movement'!$F$2:$F$501,'Stock Movement'!$D$2:$D$501,E14,'Stock Movement'!$E$2:$E$501,"IN")-SUMIFS('Stock Movement'!$F$2:$F$501,'Stock Movement'!$D$2:$D$501,E14,'Stock Movement'!$E$2:$E$501,"OUT")) -> 0 | K14: {=IF(G14="","",IFERROR(INDEX('Material Master'!$D$2:$D$201,IFERROR(MATCH(G14,'Material Master'!$F$2:$F$201,0),MATCH(G14,'Material Master'!$A$2:$A$201,0))),""))} | L14: LOT-2026-WN20
A15: R01 | B15: 1 | C15: GL1 | D15: A3 | E15: =IF(COUNTA(A15:D15)=0,"",A15&"-"&"B"&TEXT(B15,"00")&"-"&C15&"-"&D15) -> R01-B01-GL1-A3 | F15: =IF(E15="","",IF(J15>0,"Occupied","Available")) -> Available | G15: MAT047 (ALL FRUIT FORK S/4) | H15: {=IF(G15="","",IFERROR(INDEX('Material Master'!$B$2:$B$201,IFERROR(MATCH(G15,'Material Master'!$F$2:$F$201,0),MATCH(G15,'Material Master'!$A$2:$A$201,0))),""))} -> ALL FRUIT FORK S/4 | I15: {=IF(G15="","",IFERROR(INDEX('Material Master'!$C$2:$C$201,IFERROR(MATCH(G15,'Material Master'!$F$2:$F$201,0),MATCH(G15,'Material Master'!$A$2:$A$201,0))),""))} -> CARPENTER | J15: =IF(E15="","",SUMIFS('Stock Movement'!$F$2:$F$501,'Stock Movement'!$D$2:$D$501,E15,'Stock Movement'!$E$2:$E$501,"IN")-SUMIFS('Stock Movement'!$F$2:$F$501,'Stock Movement'!$D$2:$D$501,E15,'Stock Movement'!$E$2:$E$501,"OUT")) -> 0 | K15: {=IF(G15="","",IFERROR(INDEX('Material Master'!$D$2:$D$201,IFERROR(MATCH(G15,'Material Master'!$F$2:$F$201,0),MATCH(G15,'Material Master'!$A$2:$A$201,0))),""))} -> PCS | L15: LOT-2026-WN21
E16: =IF(COUNTA(A16:D16)=0,"",A16&"-"&"B"&TEXT(B16,"00")&"-"&C16&"-"&D16) | F16: =IF(E16="","",IF(J16>0,"Occupied","Available")) | H16: {=IF(G16="","",IFERROR(INDEX('Material Master'!$B$2:$B$201,IFERROR(MATCH(G16,'Material Master'!$F$2:$F$201,0),MATCH(G16,'Material Master'!$A$2:$A$201,0))),""))} | I16: {=IF(G16="","",IFERROR(INDEX('Material Master'!$C$2:$C$201,IFERROR(MATCH(G16,'Material Master'!$F$2:$F$201,0),MATCH(G16,'Material Master'!$A$2:$A$201,0))),""))} | J16: =IF(E16="","",SUMIFS('Stock Movement'!$F$2:$F$501,'Stock Movement'!$D$2:$D$501,E16,'Stock Movement'!$E$2:$E$501,"IN")-SUMIFS('Stock Movement'!$F$2:$F$501,'Stock Movement'!$D$2:$D$501,E16,'Stock Movement'!$E$2:$E$501,"OUT")) | K16: {=IF(G16="","",IFERROR(INDEX('Material Master'!$D$2:$D$201,IFERROR(MATCH(G16,'Material Master'!$F$2:$F$201,0),MATCH(G16,'Material Master'!$A$2:$A$201,0))),""))}
E17: =IF(COUNTA(A17:D17)=0,"",A17&"-"&"B"&TEXT(B17,"00")&"-"&C17&"-"&D17) | F17: =IF(E17="","",IF(J17>0,"Occupied","Available")) | H17: {=IF(G17="","",IFERROR(INDEX('Material Master'!$B$2:$B$201,IFERROR(MATCH(G17,'Material Master'!$F$2:$F$201,0),MATCH(G17,'Material Master'!$A$2:$A$201,0))),""))} | I17: {=IF(G17="","",IFERROR(INDEX('Material Master'!$C$2:$C$201,IFERROR(MATCH(G17,'Material Master'!$F$2:$F$201,0),MATCH(G17,'Material Master'!$A$2:$A$201,0))),""))} | J17: =IF(E17="","",SUMIFS('Stock Movement'!$F$2:$F$501,'Stock Movement'!$D$2:$D$501,E17,'Stock Movement'!$E$2:$E$501,"IN")-SUMIFS('Stock Movement'!$F$2:$F$501,'Stock Movement'!$D$2:$D$501,E17,'Stock Movement'!$E$2:$E$501,"OUT")) | K17: {=IF(G17="","",IFERROR(INDEX('Material Master'!$D$2:$D$201,IFERROR(MATCH(G17,'Material Master'!$F$2:$F$201,0),MATCH(G17,'Material Master'!$A$2:$A$201,0))),""))}
E18: =IF(COUNTA(A18:D18)=0,"",A18&"-"&"B"&TEXT(B18,"00")&"-"&C18&"-"&D18) | F18: =IF(E18="","",IF(J18>0,"Occupied","Available")) | H18: {=IF(G18="","",IFERROR(INDEX('Material Master'!$B$2:$B$201,IFERROR(MATCH(G18,'Material Master'!$F$2:$F$201,0),MATCH(G18,'Material Master'!$A$2:$A$201,0))),""))} | I18: {=IF(G18="","",IFERROR(INDEX('Material Master'!$C$2:$C$201,IFERROR(MATCH(G18,'Material Master'!$F$2:$F$201,0),MATCH(G18,'Material Master'!$A$2:$A$201,0))),""))} | J18: =IF(E18="","",SUMIFS('Stock Movement'!$F$2:$F$501,'Stock Movement'!$D$2:$D$501,E18,'Stock Movement'!$E$2:$E$501,"IN")-SUMIFS('Stock Movement'!$F$2:$F$501,'Stock Movement'!$D$2:$D$501,E18,'Stock Movement'!$E$2:$E$501,"OUT")) | K18: {=IF(G18="","",IFERROR(INDEX('Material Master'!$D$2:$D$201,IFERROR(MATCH(G18,'Material Master'!$F$2:$F$201,0),MATCH(G18,'Material Master'!$A$2:$A$201,0))),""))}
E19: =IF(COUNTA(A19:D19)=0,"",A19&"-"&"B"&TEXT(B19,"00")&"-"&C19&"-"&D19) | F19: =IF(E19="","",IF(J19>0,"Occupied","Available")) | H19: {=IF(G19="","",IFERROR(INDEX('Material Master'!$B$2:$B$201,IFERROR(MATCH(G19,'Material Master'!$F$2:$F$201,0),MATCH(G19,'Material Master'!$A$2:$A$201,0))),""))} | I19: {=IF(G19="","",IFERROR(INDEX('Material Master'!$C$2:$C$201,IFERROR(MATCH(G19,'Material Master'!$F$2:$F$201,0),MATCH(G19,'Material Master'!$A$2:$A$201,0))),""))} | J19: =IF(E19="","",SUMIFS('Stock Movement'!$F$2:$F$501,'Stock Movement'!$D$2:$D$501,E19,'Stock Movement'!$E$2:$E$501,"IN")-SUMIFS('Stock Movement'!$F$2:$F$501,'Stock Movement'!$D$2:$D$501,E19,'Stock Movement'!$E$2:$E$501,"OUT")) | K19: {=IF(G19="","",IFERROR(INDEX('Material Master'!$D$2:$D$201,IFERROR(MATCH(G19,'Material Master'!$F$2:$F$201,0),MATCH(G19,'Material Master'!$A$2:$A$201,0))),""))}
E20: =IF(COUNTA(A20:D20)=0,"",A20&"-"&"B"&TEXT(B20,"00")&"-"&C20&"-"&D20) | F20: =IF(E20="","",IF(J20>0,"Occupied","Available")) | H20: {=IF(G20="","",IFERROR(INDEX('Material Master'!$B$2:$B$201,IFERROR(MATCH(G20,'Material Master'!$F$2:$F$201,0),MATCH(G20,'Material Master'!$A$2:$A$201,0))),""))} | I20: {=IF(G20="","",IFERROR(INDEX('Material Master'!$C$2:$C$201,IFERROR(MATCH(G20,'Material Master'!$F$2:$F$201,0),MATCH(G20,'Material Master'!$A$2:$A$201,0))),""))} | J20: =IF(E20="","",SUMIFS('Stock Movement'!$F$2:$F$501,'Stock Movement'!$D$2:$D$501,E20,'Stock Movement'!$E$2:$E$501,"IN")-SUMIFS('Stock Movement'!$F$2:$F$501,'Stock Movement'!$D$2:$D$501,E20,'Stock Movement'!$E$2:$E$501,"OUT")) | K20: {=IF(G20="","",IFERROR(INDEX('Material Master'!$D$2:$D$201,IFERROR(MATCH(G20,'Material Master'!$F$2:$F$201,0),MATCH(G20,'Material Master'!$A$2:$A$201,0))),""))}
E21: =IF(COUNTA(A21:D21)=0,"",A21&"-"&"B"&TEXT(B21,"00")&"-"&C21&"-"&D21) | F21: =IF(E21="","",IF(J21>0,"Occupied","Available")) | H21: {=IF(G21="","",IFERROR(INDEX('Material Master'!$B$2:$B$201,IFERROR(MATCH(G21,'Material Master'!$F$2:$F$201,0),MATCH(G21,'Material Master'!$A$2:$A$201,0))),""))} | I21: {=IF(G21="","",IFERROR(INDEX('Material Master'!$C$2:$C$201,IFERROR(MATCH(G21,'Material Master'!$F$2:$F$201,0),MATCH(G21,'Material Master'!$A$2:$A$201,0))),""))} | J21: =IF(E21="","",SUMIFS('Stock Movement'!$F$2:$F$501,'Stock Movement'!$D$2:$D$501,E21,'Stock Movement'!$E$2:$E$501,"IN")-SUMIFS('Stock Movement'!$F$2:$F$501,'Stock Movement'!$D$2:$D$501,E21,'Stock Movement'!$E$2:$E$501,"OUT")) | K21: {=IF(G21="","",IFERROR(INDEX('Material Master'!$D$2:$D$201,IFERROR(MATCH(G21,'Material Master'!$F$2:$F$201,0),MATCH(G21,'Material Master'!$A$2:$A$201,0))),""))}
E22: =IF(COUNTA(A22:D22)=0,"",A22&"-"&"B"&TEXT(B22,"00")&"-"&C22&"-"&D22) | F22: =IF(E22="","",IF(J22>0,"Occupied","Available")) | H22: {=IF(G22="","",IFERROR(INDEX('Material Master'!$B$2:$B$201,IFERROR(MATCH(G22,'Material Master'!$F$2:$F$201,0),MATCH(G22,'Material Master'!$A$2:$A$201,0))),""))} | I22: {=IF(G22="","",IFERROR(INDEX('Material Master'!$C$2:$C$201,IFERROR(MATCH(G22,'Material Master'!$F$2:$F$201,0),MATCH(G22,'Material Master'!$A$2:$A$201,0))),""))} | J22: =IF(E22="","",SUMIFS('Stock Movement'!$F$2:$F$501,'Stock Movement'!$D$2:$D$501,E22,'Stock Movement'!$E$2:$E$501,"IN")-SUMIFS('Stock Movement'!$F$2:$F$501,'Stock Movement'!$D$2:$D$501,E22,'Stock Movement'!$E$2:$E$501,"OUT")) | K22: {=IF(G22="","",IFERROR(INDEX('Material Master'!$D$2:$D$201,IFERROR(MATCH(G22,'Material Master'!$F$2:$F$201,0),MATCH(G22,'Material Master'!$A$2:$A$201,0))),""))}
E23: =IF(COUNTA(A23:D23)=0,"",A23&"-"&"B"&TEXT(B23,"00")&"-"&C23&"-"&D23) | F23: =IF(E23="","",IF(J23>0,"Occupied","Available")) | H23: {=IF(G23="","",IFERROR(INDEX('Material Master'!$B$2:$B$201,IFERROR(MATCH(G23,'Material Master'!$F$2:$F$201,0),MATCH(G23,'Material Master'!$A$2:$A$201,0))),""))} | I23: {=IF(G23="","",IFERROR(INDEX('Material Master'!$C$2:$C$201,IFERROR(MATCH(G23,'Material Master'!$F$2:$F$201,0),MATCH(G23,'Material Master'!$A$2:$A$201,0))),""))} | J23: =IF(E23="","",SUMIFS('Stock Movement'!$F$2:$F$501,'Stock Movement'!$D$2:$D$501,E23,'Stock Movement'!$E$2:$E$501,"IN")-SUMIFS('Stock Movement'!$F$2:$F$501,'Stock Movement'!$D$2:$D$501,E23,'Stock Movement'!$E$2:$E$501,"OUT")) | K23: {=IF(G23="","",IFERROR(INDEX('Material Master'!$D$2:$D$201,IFERROR(MATCH(G23,'Material Master'!$F$2:$F$201,0),MATCH(G23,'Material Master'!$A$2:$A$201,0))),""))}
E24: =IF(COUNTA(A24:D24)=0,"",A24&"-"&"B"&TEXT(B24,"00")&"-"&C24&"-"&D24) | F24: =IF(E24="","",IF(J24>0,"Occupied","Available")) | H24: {=IF(G24="","",IFERROR(INDEX('Material Master'!$B$2:$B$201,IFERROR(MATCH(G24,'Material Master'!$F$2:$F$201,0),MATCH(G24,'Material Master'!$A$2:$A$201,0))),""))} | I24: {=IF(G24="","",IFERROR(INDEX('Material Master'!$C$2:$C$201,IFERROR(MATCH(G24,'Material Master'!$F$2:$F$201,0),MATCH(G24,'Material Master'!$A$2:$A$201,0))),""))} | J24: =IF(E24="","",SUMIFS('Stock Movement'!$F$2:$F$501,'Stock Movement'!$D$2:$D$501,E24,'Stock Movement'!$E$2:$E$501,"IN")-SUMIFS('Stock Movement'!$F$2:$F$501,'Stock Movement'!$D$2:$D$501,E24,'Stock Movement'!$E$2:$E$501,"OUT")) | K24: {=IF(G24="","",IFERROR(INDEX('Material Master'!$D$2:$D$201,IFERROR(MATCH(G24,'Material Master'!$F$2:$F$201,0),MATCH(G24,'Material Master'!$A$2:$A$201,0))),""))}
E25: =IF(COUNTA(A25:D25)=0,"",A25&"-"&"B"&TEXT(B25,"00")&"-"&C25&"-"&D25) | F25: =IF(E25="","",IF(J25>0,"Occupied","Available")) | H25: {=IF(G25="","",IFERROR(INDEX('Material Master'!$B$2:$B$201,IFERROR(MATCH(G25,'Material Master'!$F$2:$F$201,0),MATCH(G25,'Material Master'!$A$2:$A$201,0))),""))} | I25: {=IF(G25="","",IFERROR(INDEX('Material Master'!$C$2:$C$201,IFERROR(MATCH(G25,'Material Master'!$F$2:$F$201,0),MATCH(G25,'Material Master'!$A$2:$A$201,0))),""))} | J25: =IF(E25="","",SUMIFS('Stock Movement'!$F$2:$F$501,'Stock Movement'!$D$2:$D$501,E25,'Stock Movement'!$E$2:$E$501,"IN")-SUMIFS('Stock Movement'!$F$2:$F$501,'Stock Movement'!$D$2:$D$501,E25,'Stock Movement'!$E$2:$E$501,"OUT")) | K25: {=IF(G25="","",IFERROR(INDEX('Material Master'!$D$2:$D$201,IFERROR(MATCH(G25,'Material Master'!$F$2:$F$201,0),MATCH(G25,'Material Master'!$A$2:$A$201,0))),""))}
E26: =IF(COUNTA(A26:D26)=0,"",A26&"-"&"B"&TEXT(B26,"00")&"-"&C26&"-"&D26) | F26: =IF(E26="","",IF(J26>0,"Occupied","Available")) | H26: {=IF(G26="","",IFERROR(INDEX('Material Master'!$B$2:$B$201,IFERROR(MATCH(G26,'Material Master'!$F$2:$F$201,0),MATCH(G26,'Material Master'!$A$2:$A$201,0))),""))} | I26: {=IF(G26="","",IFERROR(INDEX('Material Master'!$C$2:$C$201,IFERROR(MATCH(G26,'Material Master'!$F$2:$F$201,0),MATCH(G26,'Material Master'!$A$2:$A$201,0))),""))} | J26: =IF(E26="","",SUMIFS('Stock Movement'!$F$2:$F$501,'Stock Movement'!$D$2:$D$501,E26,'Stock Movement'!$E$2:$E$501,"IN")-SUMIFS('Stock Movement'!$F$2:$F$501,'Stock Movement'!$D$2:$D$501,E26,'Stock Movement'!$E$2:$E$501,"OUT")) | K26: {=IF(G26="","",IFERROR(INDEX('Material Master'!$D$2:$D$201,IFERROR(MATCH(G26,'Material Master'!$F$2:$F$201,0),MATCH(G26,'Material Master'!$A$2:$A$201,0))),""))}
E27: =IF(COUNTA(A27:D27)=0,"",A27&"-"&"B"&TEXT(B27,"00")&"-"&C27&"-"&D27) | F27: =IF(E27="","",IF(J27>0,"Occupied","Available")) | H27: {=IF(G27="","",IFERROR(INDEX('Material Master'!$B$2:$B$201,IFERROR(MATCH(G27,'Material Master'!$F$2:$F$201,0),MATCH(G27,'Material Master'!$A$2:$A$201,0))),""))} | I27: {=IF(G27="","",IFERROR(INDEX('Material Master'!$C$2:$C$201,IFERROR(MATCH(G27,'Material Master'!$F$2:$F$201,0),MATCH(G27,'Material Master'!$A$2:$A$201,0))),""))} | J27: =IF(E27="","",SUMIFS('Stock Movement'!$F$2:$F$501,'Stock Movement'!$D$2:$D$501,E27,'Stock Movement'!$E$2:$E$501,"IN")-SUMIFS('Stock Movement'!$F$2:$F$501,'Stock Movement'!$D$2:$D$501,E27,'Stock Movement'!$E$2:$E$501,"OUT")) | K27: {=IF(G27="","",IFERROR(INDEX('Material Master'!$D$2:$D$201,IFERROR(MATCH(G27,'Material Master'!$F$2:$F$201,0),MATCH(G27,'Material Master'!$A$2:$A$201,0))),""))}
... E502: =IF(COUNTA(A502:D502)=0,"",A502&"-"&"B"&TEXT(B502,"00")&"-"&C502&"-"&D502) | F502: =IF(E502="","",IF(J502>0,"Occupied","Available")) | H502: {=IF(G502="","",IFERROR(INDEX('Material Master'!$B$2:$B$201,IFERROR(MATCH(G502,'Material Master'!$F$2:$F$201,0),MATCH(G502,'Material Master'!$A$2:$A$201,0))),""))} | I502: {=IF(G502="","",IFERROR(INDEX('Material Master'!$C$2:$C$201,IFERROR(MATCH(G502,'Material Master'!$F$2:$F$201,0),MATCH(G502,'Material Master'!$A$2:$A$201,0))),""))} | J502: =IF(E502="","",SUMIFS('Stock Movement'!$F$2:$F$501,'Stock Movement'!$D$2:$D$501,E502,'Stock Movement'!$E$2:$E$501,"IN")-SUMIFS('Stock Movement'!$F$2:$F$501,'Stock Movement'!$D$2:$D$501,E502,'Stock Movement'!$E$2:$E$501,"OUT")) | K502: {=IF(G502="","",IFERROR(INDEX('Material Master'!$D$2:$D$201,IFERROR(MATCH(G502,'Material Master'!$F$2:$F$201,0),MATCH(G502,'Material Master'!$A$2:$A$201,0))),""))}
A503: R01 | B503: 1 | C503: SL6 | D503: A | E503: =IF(COUNTA(A503:D503)=0,"",A503&"-"&"B"&TEXT(B503,"00")&"-"&C503&"-"&D503) -> R01-B01-SL6-A | F503: =IF(E503="","",IF(J503>0,"Occupied","Available")) -> Available | H503: {=IF(G503="","",IFERROR(INDEX('Material Master'!$B$2:$B$201,IFERROR(MATCH(G503,'Material Master'!$F$2:$F$201,0),MATCH(G503,'Material Master'!$A$2:$A$201,0))),""))} | I503: {=IF(G503="","",IFERROR(INDEX('Material Master'!$C$2:$C$201,IFERROR(MATCH(G503,'Material Master'!$F$2:$F$201,0),MATCH(G503,'Material Master'!$A$2:$A$201,0))),""))} | J503: =IF(E503="","",SUMIFS('Stock Movement'!$F$2:$F$501,'Stock Movement'!$D$2:$D$501,E503,'Stock Movement'!$E$2:$E$501,"IN")-SUMIFS('Stock Movement'!$F$2:$F$501,'Stock Movement'!$D$2:$D$501,E503,'Stock Movement'!$E$2:$E$501,"OUT")) -> 0 | K503: {=IF(G503="","",IFERROR(INDEX('Material Master'!$D$2:$D$201,IFERROR(MATCH(G503,'Material Master'!$F$2:$F$201,0),MATCH(G503,'Material Master'!$A$2:$A$201,0))),""))} | M503: Generated for Rack R01
A504: R01 | B504: 1 | C504: SL6 | D504: B | E504: =IF(COUNTA(A504:D504)=0,"",A504&"-"&"B"&TEXT(B504,"00")&"-"&C504&"-"&D504) -> R01-B01-SL6-B | F504: =IF(E504="","",IF(J504>0,"Occupied","Available")) -> Available | H504: {=IF(G504="","",IFERROR(INDEX('Material Master'!$B$2:$B$201,IFERROR(MATCH(G504,'Material Master'!$F$2:$F$201,0),MATCH(G504,'Material Master'!$A$2:$A$201,0))),""))} | I504: {=IF(G504="","",IFERROR(INDEX('Material Master'!$C$2:$C$201,IFERROR(MATCH(G504,'Material Master'!$F$2:$F$201,0),MATCH(G504,'Material Master'!$A$2:$A$201,0))),""))} | J504: =IF(E504="","",SUMIFS('Stock Movement'!$F$2:$F$501,'Stock Movement'!$D$2:$D$501,E504,'Stock Movement'!$E$2:$E$501,"IN")-SUMIFS('Stock Movement'!$F$2:$F$501,'Stock Movement'!$D$2:$D$501,E504,'Stock Movement'!$E$2:$E$501,"OUT")) -> 0 | K504: {=IF(G504="","",IFERROR(INDEX('Material Master'!$D$2:$D$201,IFERROR(MATCH(G504,'Material Master'!$F$2:$F$201,0),MATCH(G504,'Material Master'!$A$2:$A$201,0))),""))} | M504: Generated for Rack R01
A505: R01 | B505: 1 | C505: SL5 | D505: A | E505: =IF(COUNTA(A505:D505)=0,"",A505&"-"&"B"&TEXT(B505,"00")&"-"&C505&"-"&D505) -> R01-B01-SL5-A | F505: =IF(E505="","",IF(J505>0,"Occupied","Available")) -> Available | H505: {=IF(G505="","",IFERROR(INDEX('Material Master'!$B$2:$B$201,IFERROR(MATCH(G505,'Material Master'!$F$2:$F$201,0),MATCH(G505,'Material Master'!$A$2:$A$201,0))),""))} | I505: {=IF(G505="","",IFERROR(INDEX('Material Master'!$C$2:$C$201,IFERROR(MATCH(G505,'Material Master'!$F$2:$F$201,0),MATCH(G505,'Material Master'!$A$2:$A$201,0))),""))} | J505: =IF(E505="","",SUMIFS('Stock Movement'!$F$2:$F$501,'Stock Movement'!$D$2:$D$501,E505,'Stock Movement'!$E$2:$E$501,"IN")-SUMIFS('Stock Movement'!$F$2:$F$501,'Stock Movement'!$D$2:$D$501,E505,'Stock Movement'!$E$2:$E$501,"OUT")) -> 0 | K505: {=IF(G505="","",IFERROR(INDEX('Material Master'!$D$2:$D$201,IFERROR(MATCH(G505,'Material Master'!$F$2:$F$201,0),MATCH(G505,'Material Master'!$A$2:$A$201,0))),""))} | M505: Generated for Rack R01
A506: R01 | B506: 1 | C506: SL5 | D506: B | E506: =IF(COUNTA(A506:D506)=0,"",A506&"-"&"B"&TEXT(B506,"00")&"-"&C506&"-"&D506) -> R01-B01-SL5-B | F506: =IF(E506="","",IF(J506>0,"Occupied","Available")) -> Available | H506: {=IF(G506="","",IFERROR(INDEX('Material Master'!$B$2:$B$201,IFERROR(MATCH(G506,'Material Master'!$F$2:$F$201,0),MATCH(G506,'Material Master'!$A$2:$A$201,0))),""))} | I506: {=IF(G506="","",IFERROR(INDEX('Material Master'!$C$2:$C$201,IFERROR(MATCH(G506,'Material Master'!$F$2:$F$201,0),MATCH(G506,'Material Master'!$A$2:$A$201,0))),""))} | J506: =IF(E506="","",SUMIFS('Stock Movement'!$F$2:$F$501,'Stock Movement'!$D$2:$D$501,E506,'Stock Movement'!$E$2:$E$501,"IN")-SUMIFS('Stock Movement'!$F$2:$F$501,'Stock Movement'!$D$2:$D$501,E506,'Stock Movement'!$E$2:$E$501,"OUT")) -> 0 | K506: {=IF(G506="","",IFERROR(INDEX('Material Master'!$D$2:$D$201,IFERROR(MATCH(G506,'Material Master'!$F$2:$F$201,0),MATCH(G506,'Material Master'!$A$2:$A$201,0))),""))} | M506: Generated for Rack R01
A507: R01 | B507: 1 | C507: SL4 | D507: A | E507: =IF(COUNTA(A507:D507)=0,"",A507&"-"&"B"&TEXT(B507,"00")&"-"&C507&"-"&D507) -> R01-B01-SL4-A | F507: =IF(E507="","",IF(J507>0,"Occupied","Available")) -> Available | H507: {=IF(G507="","",IFERROR(INDEX('Material Master'!$B$2:$B$201,IFERROR(MATCH(G507,'Material Master'!$F$2:$F$201,0),MATCH(G507,'Material Master'!$A$2:$A$201,0))),""))} | I507: {=IF(G507="","",IFERROR(INDEX('Material Master'!$C$2:$C$201,IFERROR(MATCH(G507,'Material Master'!$F$2:$F$201,0),MATCH(G507,'Material Master'!$A$2:$A$201,0))),""))} | J507: =IF(E507="","",SUMIFS('Stock Movement'!$F$2:$F$501,'Stock Movement'!$D$2:$D$501,E507,'Stock Movement'!$E$2:$E$501,"IN")-SUMIFS('Stock Movement'!$F$2:$F$501,'Stock Movement'!$D$2:$D$501,E507,'Stock Movement'!$E$2:$E$501,"OUT")) -> 0 | K507: {=IF(G507="","",IFERROR(INDEX('Material Master'!$D$2:$D$201,IFERROR(MATCH(G507,'Material Master'!$F$2:$F$201,0),MATCH(G507,'Material Master'!$A$2:$A$201,0))),""))} | M507: Generated for Rack R01
A508: R01 | B508: 1 | C508: SL4 | D508: B | E508: =IF(COUNTA(A508:D508)=0,"",A508&"-"&"B"&TEXT(B508,"00")&"-"&C508&"-"&D508) -> R01-B01-SL4-B | F508: =IF(E508="","",IF(J508>0,"Occupied","Available")) -> Available | H508: {=IF(G508="","",IFERROR(INDEX('Material Master'!$B$2:$B$201,IFERROR(MATCH(G508,'Material Master'!$F$2:$F$201,0),MATCH(G508,'Material Master'!$A$2:$A$201,0))),""))} | I508: {=IF(G508="","",IFERROR(INDEX('Material Master'!$C$2:$C$201,IFERROR(MATCH(G508,'Material Master'!$F$2:$F$201,0),MATCH(G508,'Material Master'!$A$2:$A$201,0))),""))} | J508: =IF(E508="","",SUMIFS('Stock Movement'!$F$2:$F$501,'Stock Movement'!$D$2:$D$501,E508,'Stock Movement'!$E$2:$E$501,"IN")-SUMIFS('Stock Movement'!$F$2:$F$501,'Stock Movement'!$D$2:$D$501,E508,'Stock Movement'!$E$2:$E$501,"OUT")) -> 0 | K508: {=IF(G508="","",IFERROR(INDEX('Material Master'!$D$2:$D$201,IFERROR(MATCH(G508,'Material Master'!$F$2:$F$201,0),MATCH(G508,'Material Master'!$A$2:$A$201,0))),""))} | M508: Generated for Rack R01
A509: R01 | B509: 2 | C509: SL6 | D509: A | E509: =IF(COUNTA(A509:D509)=0,"",A509&"-"&"B"&TEXT(B509,"00")&"-"&C509&"-"&D509) -> R01-B02-SL6-A | F509: =IF(E509="","",IF(J509>0,"Occupied","Available")) -> Available | H509: {=IF(G509="","",IFERROR(INDEX('Material Master'!$B$2:$B$201,IFERROR(MATCH(G509,'Material Master'!$F$2:$F$201,0),MATCH(G509,'Material Master'!$A$2:$A$201,0))),""))} | I509: {=IF(G509="","",IFERROR(INDEX('Material Master'!$C$2:$C$201,IFERROR(MATCH(G509,'Material Master'!$F$2:$F$201,0),MATCH(G509,'Material Master'!$A$2:$A$201,0))),""))} | J509: =IF(E509="","",SUMIFS('Stock Movement'!$F$2:$F$501,'Stock Movement'!$D$2:$D$501,E509,'Stock Movement'!$E$2:$E$501,"IN")-SUMIFS('Stock Movement'!$F$2:$F$501,'Stock Movement'!$D$2:$D$501,E509,'Stock Movement'!$E$2:$E$501,"OUT")) -> 0 | K509: {=IF(G509="","",IFERROR(INDEX('Material Master'!$D$2:$D$201,IFERROR(MATCH(G509,'Material Master'!$F$2:$F$201,0),MATCH(G509,'Material Master'!$A$2:$A$201,0))),""))} | M509: Generated for Rack R01
A510: R01 | B510: 2 | C510: SL6 | D510: B | E510: =IF(COUNTA(A510:D510)=0,"",A510&"-"&"B"&TEXT(B510,"00")&"-"&C510&"-"&D510) -> R01-B02-SL6-B | F510: =IF(E510="","",IF(J510>0,"Occupied","Available")) -> Available | H510: {=IF(G510="","",IFERROR(INDEX('Material Master'!$B$2:$B$201,IFERROR(MATCH(G510,'Material Master'!$F$2:$F$201,0),MATCH(G510,'Material Master'!$A$2:$A$201,0))),""))} | I510: {=IF(G510="","",IFERROR(INDEX('Material Master'!$C$2:$C$201,IFERROR(MATCH(G510,'Material Master'!$F$2:$F$201,0),MATCH(G510,'Material Master'!$A$2:$A$201,0))),""))} | J510: =IF(E510="","",SUMIFS('Stock Movement'!$F$2:$F$501,'Stock Movement'!$D$2:$D$501,E510,'Stock Movement'!$E$2:$E$501,"IN")-SUMIFS('Stock Movement'!$F$2:$F$501,'Stock Movement'!$D$2:$D$501,E510,'Stock Movement'!$E$2:$E$501,"OUT")) -> 0 | K510: {=IF(G510="","",IFERROR(INDEX('Material Master'!$D$2:$D$201,IFERROR(MATCH(G510,'Material Master'!$F$2:$F$201,0),MATCH(G510,'Material Master'!$A$2:$A$201,0))),""))} | M510: Generated for Rack R01
A511: R01 | B511: 2 | C511: SL5 | D511: A | E511: =IF(COUNTA(A511:D511)=0,"",A511&"-"&"B"&TEXT(B511,"00")&"-"&C511&"-"&D511) -> R01-B02-SL5-A | F511: =IF(E511="","",IF(J511>0,"Occupied","Available")) -> Available | H511: {=IF(G511="","",IFERROR(INDEX('Material Master'!$B$2:$B$201,IFERROR(MATCH(G511,'Material Master'!$F$2:$F$201,0),MATCH(G511,'Material Master'!$A$2:$A$201,0))),""))} | I511: {=IF(G511="","",IFERROR(INDEX('Material Master'!$C$2:$C$201,IFERROR(MATCH(G511,'Material Master'!$F$2:$F$201,0),MATCH(G511,'Material Master'!$A$2:$A$201,0))),""))} | J511: =IF(E511="","",SUMIFS('Stock Movement'!$F$2:$F$501,'Stock Movement'!$D$2:$D$501,E511,'Stock Movement'!$E$2:$E$501,"IN")-SUMIFS('Stock Movement'!$F$2:$F$501,'Stock Movement'!$D$2:$D$501,E511,'Stock Movement'!$E$2:$E$501,"OUT")) -> 0 | K511: {=IF(G511="","",IFERROR(INDEX('Material Master'!$D$2:$D$201,IFERROR(MATCH(G511,'Material Master'!$F$2:$F$201,0),MATCH(G511,'Material Master'!$A$2:$A$201,0))),""))} | M511: Generated for Rack R01
A512: R01 | B512: 2 | C512: SL5 | D512: B | E512: =IF(COUNTA(A512:D512)=0,"",A512&"-"&"B"&TEXT(B512,"00")&"-"&C512&"-"&D512) -> R01-B02-SL5-B | F512: =IF(E512="","",IF(J512>0,"Occupied","Available")) -> Available | H512: {=IF(G512="","",IFERROR(INDEX('Material Master'!$B$2:$B$201,IFERROR(MATCH(G512,'Material Master'!$F$2:$F$201,0),MATCH(G512,'Material Master'!$A$2:$A$201,0))),""))} | I512: {=IF(G512="","",IFERROR(INDEX('Material Master'!$C$2:$C$201,IFERROR(MATCH(G512,'Material Master'!$F$2:$F$201,0),MATCH(G512,'Material Master'!$A$2:$A$201,0))),""))} | J512: =IF(E512="","",SUMIFS('Stock Movement'!$F$2:$F$501,'Stock Movement'!$D$2:$D$501,E512,'Stock Movement'!$E$2:$E$501,"IN")-SUMIFS('Stock Movement'!$F$2:$F$501,'Stock Movement'!$D$2:$D$501,E512,'Stock Movement'!$E$2:$E$501,"OUT")) -> 0 | K512: {=IF(G512="","",IFERROR(INDEX('Material Master'!$D$2:$D$201,IFERROR(MATCH(G512,'Material Master'!$F$2:$F$201,0),MATCH(G512,'Material Master'!$A$2:$A$201,0))),""))} | M512: Generated for Rack R01
A513: R01 | B513: 2 | C513: SL4 | D513: A | E513: =IF(COUNTA(A513:D513)=0,"",A513&"-"&"B"&TEXT(B513,"00")&"-"&C513&"-"&D513) -> R01-B02-SL4-A | F513: =IF(E513="","",IF(J513>0,"Occupied","Available")) -> Available | H513: {=IF(G513="","",IFERROR(INDEX('Material Master'!$B$2:$B$201,IFERROR(MATCH(G513,'Material Master'!$F$2:$F$201,0),MATCH(G513,'Material Master'!$A$2:$A$201,0))),""))} | I513: {=IF(G513="","",IFERROR(INDEX('Material Master'!$C$2:$C$201,IFERROR(MATCH(G513,'Material Master'!$F$2:$F$201,0),MATCH(G513,'Material Master'!$A$2:$A$201,0))),""))} | J513: =IF(E513="","",SUMIFS('Stock Movement'!$F$2:$F$501,'Stock Movement'!$D$2:$D$501,E513,'Stock Movement'!$E$2:$E$501,"IN")-SUMIFS('Stock Movement'!$F$2:$F$501,'Stock Movement'!$D$2:$D$501,E513,'Stock Movement'!$E$2:$E$501,"OUT")) -> 0 | K513: {=IF(G513="","",IFERROR(INDEX('Material Master'!$D$2:$D$201,IFERROR(MATCH(G513,'Material Master'!$F$2:$F$201,0),MATCH(G513,'Material Master'!$A$2:$A$201,0))),""))} | M513: Generated for Rack R01
A514: R01 | B514: 2 | C514: SL4 | D514: B | E514: =IF(COUNTA(A514:D514)=0,"",A514&"-"&"B"&TEXT(B514,"00")&"-"&C514&"-"&D514) -> R01-B02-SL4-B | F514: =IF(E514="","",IF(J514>0,"Occupied","Available")) -> Available | H514: {=IF(G514="","",IFERROR(INDEX('Material Master'!$B$2:$B$201,IFERROR(MATCH(G514,'Material Master'!$F$2:$F$201,0),MATCH(G514,'Material Master'!$A$2:$A$201,0))),""))} | I514: {=IF(G514="","",IFERROR(INDEX('Material Master'!$C$2:$C$201,IFERROR(MATCH(G514,'Material Master'!$F$2:$F$201,0),MATCH(G514,'Material Master'!$A$2:$A$201,0))),""))} | J514: =IF(E514="","",SUMIFS('Stock Movement'!$F$2:$F$501,'Stock Movement'!$D$2:$D$501,E514,'Stock Movement'!$E$2:$E$501,"IN")-SUMIFS('Stock Movement'!$F$2:$F$501,'Stock Movement'!$D$2:$D$501,E514,'Stock Movement'!$E$2:$E$501,"OUT")) -> 0 | K514: {=IF(G514="","",IFERROR(INDEX('Material Master'!$D$2:$D$201,IFERROR(MATCH(G514,'Material Master'!$F$2:$F$201,0),MATCH(G514,'Material Master'!$A$2:$A$201,0))),""))} | M514: Generated for Rack R01
...

Sheet Stock Movement
A1: Date | B1: Material ID | C1: Material Description | D1: Location ID | E1: Transaction Type | F1: Quantity | G1: Unit | H1: Reference | I1: User | J1: Notes
A2: 46290 | B2: MAT001 | C2: =IF(B2="","",IFERROR(VLOOKUP(B2,'Material Master'!$A$2:$E$201,2,FALSE),"")) -> BUBBLE WRAP | D2: {=IF(B2="","",IFERROR(INDEX('Location Master'!$E$2:$E$502, IFERROR(MATCH(B2,'Location Master'!$G$2:$G$502,0), IFERROR(MATCH(B2&" (*",'Location Master'!$G$2:$G$502,0), MATCH(B2&"*",'Location Master'!$G$2:$G$502,0)))), ""))} -> R01-B01-GL1-A1 | E2: IN | F2: 5 | G2: =IF(B2="","",IFERROR(VLOOKUP(B2,'Material Master'!$A$2:$E$201,4,FALSE),"")) -> PCS | H2: PO-1001 | I2: Sanika | J2: Initial purchase order receipt
A3: 46293 | B3: MAT001 | C3: =IF(B3="","",IFERROR(VLOOKUP(B3,'Material Master'!$A$2:$E$201,2,FALSE),"")) -> BUBBLE WRAP | D3: {=IF(B3="","",IFERROR(INDEX('Location Master'!$E$2:$E$502, IFERROR(MATCH(B3,'Location Master'!$G$2:$G$502,0), IFERROR(MATCH(B3&" (*",'Location Master'!$G$2:$G$502,0), MATCH(B3&"*",'Location Master'!$G$2:$G$502,0)))), ""))} -> R01-B01-GL1-A1 | E3: OUT | F3: 3 | G3: =IF(B3="","",IFERROR(VLOOKUP(B3,'Material Master'!$A$2:$E$201,4,FALSE),"")) -> PCS | H3: SO-2041 | I3: Sanika | J3: Dispatched to packing station
A4: 46291 | B4: MAT002 | C4: =IF(B4="","",IFERROR(VLOOKUP(B4,'Material Master'!$A$2:$E$201,2,FALSE),"")) -> CANDLE_LUGNARE_SCNTD | D4: {=IF(B4="","",IFERROR(INDEX('Location Master'!$E$2:$E$502, IFERROR(MATCH(B4,'Location Master'!$G$2:$G$502,0), IFERROR(MATCH(B4&" (*",'Location Master'!$G$2:$G$502,0), MATCH(B4&"*",'Location Master'!$G$2:$G$502,0)))), ""))} -> R01-B01-GL1-B | E4: IN | F4: 150 | G4: =IF(B4="","",IFERROR(VLOOKUP(B4,'Material Master'!$A$2:$E$201,4,FALSE),"")) -> PCS | H4: PO-1002 | I4: Pravin | J4: Bulk shipment received
A5: 46294 | B5: MAT002 | C5: =IF(B5="","",IFERROR(VLOOKUP(B5,'Material Master'!$A$2:$E$201,2,FALSE),"")) -> CANDLE_LUGNARE_SCNTD | D5: {=IF(B5="","",IFERROR(INDEX('Location Master'!$E$2:$E$502, IFERROR(MATCH(B5,'Location Master'!$G$2:$G$502,0), IFERROR(MATCH(B5&" (*",'Location Master'!$G$2:$G$502,0), MATCH(B5&"*",'Location Master'!$G$2:$G$502,0)))), ""))} -> R01-B01-GL1-B | E5: OUT | F5: 12 | G5: =IF(B5="","",IFERROR(VLOOKUP(B5,'Material Master'!$A$2:$E$201,4,FALSE),"")) -> PCS | H5: SO-2042 | I5: Pravin | J5: Dispatched for retail display
A6: 46291 | B6: MAT003 | C6: =IF(B6="","",IFERROR(VLOOKUP(B6,'Material Master'!$A$2:$E$201,2,FALSE),"")) -> EXTRA MCB | D6: {=IF(B6="","",IFERROR(INDEX('Location Master'!$E$2:$E$502, IFERROR(MATCH(B6,'Location Master'!$G$2:$G$502,0), IFERROR(MATCH(B6&" (*",'Location Master'!$G$2:$G$502,0), MATCH(B6&"*",'Location Master'!$G$2:$G$502,0)))), ""))} -> R01-B01-GL2-A | E6: IN | F6: 10 | G6: =IF(B6="","",IFERROR(VLOOKUP(B6,'Material Master'!$A$2:$E$201,4,FALSE),"")) -> PCS | H6: PO-1003 | I6: Pravin | J6: Electrical spare intake
A7: 46294 | B7: MAT003 | C7: =IF(B7="","",IFERROR(VLOOKUP(B7,'Material Master'!$A$2:$E$201,2,FALSE),"")) -> EXTRA MCB | D7: {=IF(B7="","",IFERROR(INDEX('Location Master'!$E$2:$E$502, IFERROR(MATCH(B7,'Location Master'!$G$2:$G$502,0), IFERROR(MATCH(B7&" (*",'Location Master'!$G$2:$G$502,0), MATCH(B7&"*",'Location Master'!$G$2:$G$502,0)))), ""))} -> R01-B01-GL2-A | E7: OUT | F7: 9 | G7: =IF(B7="","",IFERROR(VLOOKUP(B7,'Material Master'!$A$2:$E$201,4,FALSE),"")) -> PCS | H7: SO-2043 | I7: Sanika | J7: Issued for panel maintenance
A8: 46292 | B8: MAT004 | C8: =IF(B8="","",IFERROR(VLOOKUP(B8,'Material Master'!$A$2:$E$201,2,FALSE),"")) -> FOSSIAL | D8: {=IF(B8="","",IFERROR(INDEX('Location Master'!$E$2:$E$502, IFERROR(MATCH(B8,'Location Master'!$G$2:$G$502,0), IFERROR(MATCH(B8&" (*",'Location Master'!$G$2:$G$502,0), MATCH(B8&"*",'Location Master'!$G$2:$G$502,0)))), ""))} -> R01-B01-GL2-B | E8: IN | F8: 10 | G8: =IF(B8="","",IFERROR(VLOOKUP(B8,'Material Master'!$A$2:$E$201,4,FALSE),"")) -> BAG | H8: PO-1004 | I8: Sanika | J8: Civil adhesive bag delivery
A9: 46295 | B9: MAT004 | C9: =IF(B9="","",IFERROR(VLOOKUP(B9,'Material Master'!$A$2:$E$201,2,FALSE),"")) -> FOSSIAL | D9: {=IF(B9="","",IFERROR(INDEX('Location Master'!$E$2:$E$502, IFERROR(MATCH(B9,'Location Master'!$G$2:$G$502,0), IFERROR(MATCH(B9&" (*",'Location Master'!$G$2:$G$502,0), MATCH(B9&"*",'Location Master'!$G$2:$G$502,0)))), ""))} -> R01-B01-GL2-B | E9: OUT | F9: 7 | G9: =IF(B9="","",IFERROR(VLOOKUP(B9,'Material Master'!$A$2:$E$201,4,FALSE),"")) -> BAG | H9: SO-2044 | I9: Pravin | J9: Issued to site masonry
A10: 46292 | B10: MAT005 | C10: =IF(B10="","",IFERROR(VLOOKUP(B10,'Material Master'!$A$2:$E$201,2,FALSE),"")) -> GRANITE_ AVALANCHE | D10: {=IF(B10="","",IFERROR(INDEX('Location Master'!$E$2:$E$502, IFERROR(MATCH(B10,'Location Master'!$G$2:$G$502,0), IFERROR(MATCH(B10&" (*",'Location Master'!$G$2:$G$502,0), MATCH(B10&"*",'Location Master'!$G$2:$G$502,0)))), ""))} -> R01-B02-GL1-A | E10: IN | F10: 50 | G10: =IF(B10="","",IFERROR(VLOOKUP(B10,'Material Master'!$A$2:$E$201,4,FALSE),"")) -> SQF | H10: PO-1005 | I10: Sanika | J10: Avalanche granite crate received
A11: 46294 | B11: MAT005 | C11: =IF(B11="","",IFERROR(VLOOKUP(B11,'Material Master'!$A$2:$E$201,2,FALSE),"")) -> GRANITE_ AVALANCHE | D11: {=IF(B11="","",IFERROR(INDEX('Location Master'!$E$2:$E$502, IFERROR(MATCH(B11,'Location Master'!$G$2:$G$502,0), IFERROR(MATCH(B11&" (*",'Location Master'!$G$2:$G$502,0), MATCH(B11&"*",'Location Master'!$G$2:$G$502,0)))), ""))} -> R01-B02-GL1-A | E11: OUT | F11: 10.87 | G11: =IF(B11="","",IFERROR(VLOOKUP(B11,'Material Master'!$A$2:$E$201,4,FALSE),"")) -> SQF | H11: SO-2045 | I11: Sanika | J11: Issued for countertop cutting
A12: 46293 | B12: MAT010 | C12: =IF(B12="","",IFERROR(VLOOKUP(B12,'Material Master'!$A$2:$E$201,2,FALSE),"")) -> SCREW_SELF THREAD_25X6 | D12: {=IF(B12="","",IFERROR(INDEX('Location Master'!$E$2:$E$502, IFERROR(MATCH(B12,'Location Master'!$G$2:$G$502,0), IFERROR(MATCH(B12&" (*",'Location Master'!$G$2:$G$502,0), MATCH(B12&"*",'Location Master'!$G$2:$G$502,0)))), ""))} -> R01-B02-GL2-A | E12: IN | F12: 5 | G12: =IF(B12="","",IFERROR(VLOOKUP(B12,'Material Master'!$A$2:$E$201,4,FALSE),"")) -> PCS | H12: PO-1006 | I12: Pravin | J12: Self thread screws intake
A13: 46295 | B13: MAT010 | C13: =IF(B13="","",IFERROR(VLOOKUP(B13,'Material Master'!$A$2:$E$201,2,FALSE),"")) -> SCREW_SELF THREAD_25X6 | D13: {=IF(B13="","",IFERROR(INDEX('Location Master'!$E$2:$E$502, IFERROR(MATCH(B13,'Location Master'!$G$2:$G$502,0), IFERROR(MATCH(B13&" (*",'Location Master'!$G$2:$G$502,0), MATCH(B13&"*",'Location Master'!$G$2:$G$502,0)))), ""))} -> R01-B02-GL2-A | E13: OUT | F13: 3 | G13: =IF(B13="","",IFERROR(VLOOKUP(B13,'Material Master'!$A$2:$E$201,4,FALSE),"")) -> PCS | H13: SO-2046 | I13: Pravin | J13: Dispatched for metal framing
... A21: 46295 | B21: MAT049 | C21: =IF(B21="","",IFERROR(VLOOKUP(B21,'Material Master'!$A$2:$E$201,2,FALSE),"")) -> ALL MOTTLED | D21: {=IF(B21="","",IFERROR(INDEX('Location Master'!$E$2:$E$502, IFERROR(MATCH(B21,'Location Master'!$G$2:$G$502,0), IFERROR(MATCH(B21&" (*",'Location Master'!$G$2:$G$502,0), MATCH(B21&"*",'Location Master'!$G$2:$G$502,0)))), ""))} -> R01-B02-GL1-B | E21: IN | F21: 10 | G21: =IF(B21="","",IFERROR(VLOOKUP(B21,'Material Master'!$A$2:$E$201,4,FALSE),"")) -> PCS | H21: PO-INIT | I21: Pravin | J21: Initial stock receipt upon slot assignment
C22: =IF(B22="","",IFERROR(VLOOKUP(B22,'Material Master'!$A$2:$E$201,2,FALSE),"")) | D22: {=IF(B22="","",IFERROR(INDEX('Location Master'!$E$2:$E$502, IFERROR(MATCH(B22,'Location Master'!$G$2:$G$502,0), IFERROR(MATCH(B22&" (*",'Location Master'!$G$2:$G$502,0), MATCH(B22&"*",'Location Master'!$G$2:$G$502,0)))), ""))} | G22: =IF(B22="","",IFERROR(VLOOKUP(B22,'Material Master'!$A$2:$E$201,4,FALSE),""))
C23: =IF(B23="","",IFERROR(VLOOKUP(B23,'Material Master'!$A$2:$E$201,2,FALSE),"")) | D23: {=IF(B23="","",IFERROR(INDEX('Location Master'!$E$2:$E$502, IFERROR(MATCH(B23,'Location Master'!$G$2:$G$502,0), IFERROR(MATCH(B23&" (*",'Location Master'!$G$2:$G$502,0), MATCH(B23&"*",'Location Master'!$G$2:$G$502,0)))), ""))} | G23: =IF(B23="","",IFERROR(VLOOKUP(B23,'Material Master'!$A$2:$E$201,4,FALSE),""))
C24: =IF(B24="","",IFERROR(VLOOKUP(B24,'Material Master'!$A$2:$E$201,2,FALSE),"")) | D24: {=IF(B24="","",IFERROR(INDEX('Location Master'!$E$2:$E$502, IFERROR(MATCH(B24,'Location Master'!$G$2:$G$502,0), IFERROR(MATCH(B24&" (*",'Location Master'!$G$2:$G$502,0), MATCH(B24&"*",'Location Master'!$G$2:$G$502,0)))), ""))} | G24: =IF(B24="","",IFERROR(VLOOKUP(B24,'Material Master'!$A$2:$E$201,4,FALSE),""))
C25: =IF(B25="","",IFERROR(VLOOKUP(B25,'Material Master'!$A$2:$E$201,2,FALSE),"")) | D25: {=IF(B25="","",IFERROR(INDEX('Location Master'!$E$2:$E$502, IFERROR(MATCH(B25,'Location Master'!$G$2:$G$502,0), IFERROR(MATCH(B25&" (*",'Location Master'!$G$2:$G$502,0), MATCH(B25&"*",'Location Master'!$G$2:$G$502,0)))), ""))} | G25: =IF(B25="","",IFERROR(VLOOKUP(B25,'Material Master'!$A$2:$E$201,4,FALSE),""))
C26: =IF(B26="","",IFERROR(VLOOKUP(B26,'Material Master'!$A$2:$E$201,2,FALSE),"")) | D26: {=IF(B26="","",IFERROR(INDEX('Location Master'!$E$2:$E$502, IFERROR(MATCH(B26,'Location Master'!$G$2:$G$502,0), IFERROR(MATCH(B26&" (*",'Location Master'!$G$2:$G$502,0), MATCH(B26&"*",'Location Master'!$G$2:$G$502,0)))), ""))} | G26: =IF(B26="","",IFERROR(VLOOKUP(B26,'Material Master'!$A$2:$E$201,4,FALSE),""))
C27: =IF(B27="","",IFERROR(VLOOKUP(B27,'Material Master'!$A$2:$E$201,2,FALSE),"")) | D27: {=IF(B27="","",IFERROR(INDEX('Location Master'!$E$2:$E$502, IFERROR(MATCH(B27,'Location Master'!$G$2:$G$502,0), IFERROR(MATCH(B27&" (*",'Location Master'!$G$2:$G$502,0), MATCH(B27&"*",'Location Master'!$G$2:$G$502,0)))), ""))} | G27: =IF(B27="","",IFERROR(VLOOKUP(B27,'Material Master'!$A$2:$E$201,4,FALSE),""))
C28: =IF(B28="","",IFERROR(VLOOKUP(B28,'Material Master'!$A$2:$E$201,2,FALSE),"")) | D28: {=IF(B28="","",IFERROR(INDEX('Location Master'!$E$2:$E$502, IFERROR(MATCH(B28,'Location Master'!$G$2:$G$502,0), IFERROR(MATCH(B28&" (*",'Location Master'!$G$2:$G$502,0), MATCH(B28&"*",'Location Master'!$G$2:$G$502,0)))), ""))} | G28: =IF(B28="","",IFERROR(VLOOKUP(B28,'Material Master'!$A$2:$E$201,4,FALSE),""))
C29: =IF(B29="","",IFERROR(VLOOKUP(B29,'Material Master'!$A$2:$E$201,2,FALSE),"")) | D29: {=IF(B29="","",IFERROR(INDEX('Location Master'!$E$2:$E$502, IFERROR(MATCH(B29,'Location Master'!$G$2:$G$502,0), IFERROR(MATCH(B29&" (*",'Location Master'!$G$2:$G$502,0), MATCH(B29&"*",'Location Master'!$G$2:$G$502,0)))), ""))} | G29: =IF(B29="","",IFERROR(VLOOKUP(B29,'Material Master'!$A$2:$E$201,4,FALSE),""))
C30: =IF(B30="","",IFERROR(VLOOKUP(B30,'Material Master'!$A$2:$E$201,2,FALSE),"")) | D30: {=IF(B30="","",IFERROR(INDEX('Location Master'!$E$2:$E$502, IFERROR(MATCH(B30,'Location Master'!$G$2:$G$502,0), IFERROR(MATCH(B30&" (*",'Location Master'!$G$2:$G$502,0), MATCH(B30&"*",'Location Master'!$G$2:$G$502,0)))), ""))} | G30: =IF(B30="","",IFERROR(VLOOKUP(B30,'Material Master'!$A$2:$E$201,4,FALSE),""))
C31: =IF(B31="","",IFERROR(VLOOKUP(B31,'Material Master'!$A$2:$E$201,2,FALSE),"")) | D31: {=IF(B31="","",IFERROR(INDEX('Location Master'!$E$2:$E$502, IFERROR(MATCH(B31,'Location Master'!$G$2:$G$502,0), IFERROR(MATCH(B31&" (*",'Location Master'!$G$2:$G$502,0), MATCH(B31&"*",'Location Master'!$G$2:$G$502,0)))), ""))} | G31: =IF(B31="","",IFERROR(VLOOKUP(B31,'Material Master'!$A$2:$E$201,4,FALSE),""))
C32: =IF(B32="","",IFERROR(VLOOKUP(B32,'Material Master'!$A$2:$E$201,2,FALSE),"")) | D32: {=IF(B32="","",IFERROR(INDEX('Location Master'!$E$2:$E$502, IFERROR(MATCH(B32,'Location Master'!$G$2:$G$502,0), IFERROR(MATCH(B32&" (*",'Location Master'!$G$2:$G$502,0), MATCH(B32&"*",'Location Master'!$G$2:$G$502,0)))), ""))} | G32: =IF(B32="","",IFERROR(VLOOKUP(B32,'Material Master'!$A$2:$E$201,4,FALSE),""))
C33: =IF(B33="","",IFERROR(VLOOKUP(B33,'Material Master'!$A$2:$E$201,2,FALSE),"")) | D33: {=IF(B33="","",IFERROR(INDEX('Location Master'!$E$2:$E$502, IFERROR(MATCH(B33,'Location Master'!$G$2:$G$502,0), IFERROR(MATCH(B33&" (*",'Location Master'!$G$2:$G$502,0), MATCH(B33&"*",'Location Master'!$G$2:$G$502,0)))), ""))} | G33: =IF(B33="","",IFERROR(VLOOKUP(B33,'Material Master'!$A$2:$E$201,4,FALSE),""))
... C501: =IF(B501="","",IFERROR(VLOOKUP(B501,'Material Master'!$A$2:$E$201,2,FALSE),"")) | D501: {=IF(B501="","",IFERROR(INDEX('Location Master'!$E$2:$E$502, IFERROR(MATCH(B501,'Location Master'!$G$2:$G$502,0), IFERROR(MATCH(B501&" (*",'Location Master'!$G$2:$G$502,0), MATCH(B501&"*",'Location Master'!$G$2:$G$502,0)))), ""))} | G501: =IF(B501="","",IFERROR(VLOOKUP(B501,'Material Master'!$A$2:$E$201,4,FALSE),""))

Sheet Inventory
A1: Material ID | B1: Material Description | C1: Category | D1: Location ID | E1: Opening Stock | F1: Stock IN | G1: Stock OUT | H1: Current Stock | I1: Unit | J1: Reorder Level | K1: Stock Status
A2: MAT001 | B2: =IF(A2="","",IFERROR(VLOOKUP(A2,'Material Master'!$A$2:$E$201,2,FALSE),"")) -> BUBBLE WRAP | C2: =IF(A2="","",IFERROR(VLOOKUP(A2,'Material Master'!$A$2:$E$201,3,FALSE),"")) -> PLUMBER | D2: {=IF(A2="","",IFERROR(INDEX('Location Master'!$E$2:$E$502, IFERROR(MATCH(A2,'Location Master'!$G$2:$G$502,0), IFERROR(MATCH(A2&" (*",'Location Master'!$G$2:$G$502,0), MATCH(A2&"*",'Location Master'!$G$2:$G$502,0)))), ""))} -> R01-B01-GL1-A1 | E2: 0 | F2: =IF(OR(A2="",D2=""),"",SUMIFS('Stock Movement'!$F$2:$F$501,'Stock Movement'!$B$2:$B$501,A2,'Stock Movement'!$D$2:$D$501,D2,'Stock Movement'!$E$2:$E$501,"IN")) -> 105 | G2: =IF(OR(A2="",D2=""),"",SUMIFS('Stock Movement'!$F$2:$F$501,'Stock Movement'!$B$2:$B$501,A2,'Stock Movement'!$D$2:$D$501,D2,'Stock Movement'!$E$2:$E$501,"OUT")) -> 5 | H2: =IF(A2="","",E2+F2-G2) -> 100 | I2: =IF(A2="","",IFERROR(VLOOKUP(A2,'Material Master'!$A$2:$E$201,4,FALSE),"")) -> PCS | J2: =IF(A2="","",IFERROR(VLOOKUP(A2,'Material Master'!$A$2:$E$201,5,FALSE),"")) -> 10 | K2: =IF(A2="","",IF(H2<=J2,"REORDER","OK")) -> OK
A3: MAT002 | B3: =IF(A3="","",IFERROR(VLOOKUP(A3,'Material Master'!$A$2:$E$201,2,FALSE),"")) -> CANDLE_LUGNARE_SCNTD | C3: =IF(A3="","",IFERROR(VLOOKUP(A3,'Material Master'!$A$2:$E$201,3,FALSE),"")) -> DECOR | D3: {=IF(A3="","",IFERROR(INDEX('Location Master'!$E$2:$E$502, IFERROR(MATCH(A3,'Location Master'!$G$2:$G$502,0), IFERROR(MATCH(A3&" (*",'Location Master'!$G$2:$G$502,0), MATCH(A3&"*",'Location Master'!$G$2:$G$502,0)))), ""))} -> R01-B01-GL1-B | E3: 0 | F3: =IF(OR(A3="",D3=""),"",SUMIFS('Stock Movement'!$F$2:$F$501,'Stock Movement'!$B$2:$B$501,A3,'Stock Movement'!$D$2:$D$501,D3,'Stock Movement'!$E$2:$E$501,"IN")) -> 150 | G3: =IF(OR(A3="",D3=""),"",SUMIFS('Stock Movement'!$F$2:$F$501,'Stock Movement'!$B$2:$B$501,A3,'Stock Movement'!$D$2:$D$501,D3,'Stock Movement'!$E$2:$E$501,"OUT")) -> 12 | H3: =IF(A3="","",E3+F3-G3) -> 138 | I3: =IF(A3="","",IFERROR(VLOOKUP(A3,'Material Master'!$A$2:$E$201,4,FALSE),"")) -> PCS | J3: =IF(A3="","",IFERROR(VLOOKUP(A3,'Material Master'!$A$2:$E$201,5,FALSE),"")) -> 25 | K3: =IF(A3="","",IF(H3<=J3,"REORDER","OK")) -> OK
A4: MAT003 | B4: =IF(A4="","",IFERROR(VLOOKUP(A4,'Material Master'!$A$2:$E$201,2,FALSE),"")) -> EXTRA MCB | C4: =IF(A4="","",IFERROR(VLOOKUP(A4,'Material Master'!$A$2:$E$201,3,FALSE),"")) -> ELECTRIC | D4: {=IF(A4="","",IFERROR(INDEX('Location Master'!$E$2:$E$502, IFERROR(MATCH(A4,'Location Master'!$G$2:$G$502,0), IFERROR(MATCH(A4&" (*",'Location Master'!$G$2:$G$502,0), MATCH(A4&"*",'Location Master'!$G$2:$G$502,0)))), ""))} -> R01-B01-GL2-A | E4: 0 | F4: =IF(OR(A4="",D4=""),"",SUMIFS('Stock Movement'!$F$2:$F$501,'Stock Movement'!$B$2:$B$501,A4,'Stock Movement'!$D$2:$D$501,D4,'Stock Movement'!$E$2:$E$501,"IN")) -> 10 | G4: =IF(OR(A4="",D4=""),"",SUMIFS('Stock Movement'!$F$2:$F$501,'Stock Movement'!$B$2:$B$501,A4,'Stock Movement'!$D$2:$D$501,D4,'Stock Movement'!$E$2:$E$501,"OUT")) -> 9 | H4: =IF(A4="","",E4+F4-G4) -> 1 | I4: =IF(A4="","",IFERROR(VLOOKUP(A4,'Material Master'!$A$2:$E$201,4,FALSE),"")) -> PCS | J4: =IF(A4="","",IFERROR(VLOOKUP(A4,'Material Master'!$A$2:$E$201,5,FALSE),"")) -> 5 | K4: =IF(A4="","",IF(H4<=J4,"REORDER","OK")) -> REORDER
